{
 "cells": [
  {
   "cell_type": "code",
   "execution_count": 25,
   "id": "fa9d1bbe",
   "metadata": {},
   "outputs": [],
   "source": [
    "import os\n",
    "import numpy as np\n",
    "import tensorflow as tf\n",
    "import scipy.io\n",
    "import cv2\n",
    "from tensorflow.keras import layers, Model\n",
    "from matplotlib import pyplot as plt"
   ]
  },
  {
   "cell_type": "code",
   "execution_count": 26,
   "id": "181406b5",
   "metadata": {},
   "outputs": [],
   "source": [
    "TRAIN_IMG_DIR = \"/home/nikola/Documents/Assignment-8/data/part_A/train_data/images\"\n",
    "TRAIN_GT_DIR = \"/home/nikola/Documents/Assignment-8/data/part_A/train_data/ground_truth\"\n",
    "TEST_IMG_DIR  = \"/home/nikola/Documents/Assignment-8/data/part_A/test_data/images\"\n",
    "TEST_GT_DIR   = \"/home/nikola/Documents/Assignment-8/data/part_A/test_data/ground_truth\""
   ]
  },
  {
   "cell_type": "code",
   "execution_count": 27,
   "id": "7d448416",
   "metadata": {},
   "outputs": [],
   "source": [
    "def load_density_map(mat_path):\n",
    "    mat = scipy.io.loadmat(mat_path)\n",
    "    density_map = mat[\"density\"]\n",
    "    return density_map\n",
    "\n",
    "def load_image_and_density(image_path, gt_path):\n",
    "    # Convert EagerTensors to Python strings\n",
    "    image_path = image_path.numpy().decode(\"utf-8\")\n",
    "    gt_path = gt_path.numpy().decode(\"utf-8\")\n",
    "\n",
    "    image = cv2.imread(image_path, cv2.IMREAD_COLOR)\n",
    "    image = cv2.resize(image, (256, 256)) / 255.0\n",
    "\n",
    "    density = load_density_map(gt_path)\n",
    "    density = cv2.resize(density, (64, 64))\n",
    "    density = np.expand_dims(density, axis=-1)\n",
    "\n",
    "    return image.astype(np.float32), density.astype(np.float32)\n",
    "\n",
    "def tf_load_image_and_density(image_path, gt_path):\n",
    "    image, density = tf.py_function(load_image_and_density, [image_path, gt_path], [tf.float32, tf.float32])\n",
    "    image.set_shape((256, 256, 3))\n",
    "    density.set_shape((64, 64, 1))\n",
    "    return image, density\n"
   ]
  },
  {
   "cell_type": "code",
   "execution_count": 28,
   "id": "76596279",
   "metadata": {},
   "outputs": [],
   "source": [
    "train_img_paths = sorted([os.path.join(TRAIN_IMG_DIR, f) for f in os.listdir(TRAIN_IMG_DIR) if f.endswith(\".jpg\")])\n",
    "train_gt_paths  = [p.replace(\"images\", \"ground_truth\").replace(\".jpg\", \".mat\") for p in train_img_paths]\n",
    "\n",
    "test_img_paths = sorted([os.path.join(TEST_IMG_DIR, f) for f in os.listdir(TEST_IMG_DIR) if f.endswith(\".jpg\")])\n",
    "test_gt_paths  = [p.replace(\"images\", \"ground_truth\").replace(\".jpg\", \".mat\") for p in test_img_paths]\n",
    "\n",
    "BATCH_SIZE = 8\n",
    "\n",
    "train_ds = tf.data.Dataset.from_tensor_slices((train_img_paths, train_gt_paths))\n",
    "train_ds = train_ds.map(tf_load_image_and_density, num_parallel_calls=tf.data.AUTOTUNE)\n",
    "train_ds = train_ds.shuffle(100).batch(BATCH_SIZE).prefetch(tf.data.AUTOTUNE)\n",
    "\n",
    "test_ds = tf.data.Dataset.from_tensor_slices((test_img_paths, test_gt_paths))\n",
    "test_ds = test_ds.map(tf_load_image_and_density, num_parallel_calls=tf.data.AUTOTUNE)\n",
    "test_ds = test_ds.batch(BATCH_SIZE).prefetch(tf.data.AUTOTUNE)\n"
   ]
  },
  {
   "cell_type": "code",
   "execution_count": 29,
   "id": "b1fe1bd0",
   "metadata": {},
   "outputs": [],
   "source": [
    "def unet_model(output_channels=1):\n",
    "    inputs = tf.keras.layers.Input(shape=(256, 256, 3))\n",
    "\n",
    "    # Encoder\n",
    "    x1 = layers.Conv2D(64, 3, activation='relu', padding='same')(inputs)\n",
    "    x1 = layers.Conv2D(64, 3, activation='relu', padding='same')(x1)\n",
    "    p1 = layers.MaxPooling2D((2,2))(x1)\n",
    "\n",
    "    x2 = layers.Conv2D(128, 3, activation='relu', padding='same')(p1)\n",
    "    x2 = layers.Conv2D(128, 3, activation='relu', padding='same')(x2)\n",
    "    p2 = layers.MaxPooling2D((2,2))(x2)\n",
    "\n",
    "    x3 = layers.Conv2D(256, 3, activation='relu', padding='same')(p2)\n",
    "    x3 = layers.Conv2D(256, 3, activation='relu', padding='same')(x3)\n",
    "    p3 = layers.MaxPooling2D((2,2))(x3)\n",
    "\n",
    "    # Bottleneck\n",
    "    b = layers.Conv2D(512, 3, activation='relu', padding='same')(p3)\n",
    "    b = layers.Conv2D(512, 3, activation='relu', padding='same')(b)\n",
    "\n",
    "    # Decoder\n",
    "    u1 = layers.Conv2DTranspose(256, 2, strides=2, padding='same')(b)\n",
    "    u1 = layers.concatenate([u1, x3])\n",
    "    u1 = layers.Conv2D(256, 3, activation='relu', padding='same')(u1)\n",
    "    u1 = layers.Conv2D(256, 3, activation='relu', padding='same')(u1)\n",
    "\n",
    "    u2 = layers.Conv2DTranspose(128, 2, strides=2, padding='same')(u1)\n",
    "    u2 = layers.concatenate([u2, x2])\n",
    "    u2 = layers.Conv2D(128, 3, activation='relu', padding='same')(u2)\n",
    "    u2 = layers.Conv2D(128, 3, activation='relu', padding='same')(u2)\n",
    "\n",
    "    u3 = layers.Conv2DTranspose(64, 2, strides=2, padding='same')(u2)\n",
    "    u3 = layers.concatenate([u3, x1])\n",
    "    u3 = layers.Conv2D(64, 3, activation='relu', padding='same')(u3)\n",
    "    u3 = layers.Conv2D(64, 3, activation='relu', padding='same')(u3)\n",
    "\n",
    "    outputs = layers.Conv2D(output_channels, 1, activation='linear')(u3)\n",
    "    return Model(inputs, outputs)\n"
   ]
  },
  {
   "cell_type": "code",
   "execution_count": 30,
   "id": "ba8c4a57",
   "metadata": {},
   "outputs": [
    {
     "name": "stderr",
     "output_type": "stream",
     "text": [
      "2025-07-08 00:08:30.727042: W tensorflow/core/framework/op_kernel.cc:1827] UNKNOWN: FileNotFoundError: [Errno 2] No such file or directory: '/home/nikola/Documents/Assignment-8/data/part_A/train_data/ground_truth/IMG_10.mat'\n",
      "Traceback (most recent call last):\n",
      "\n",
      "  File \"/home/nikola/.local/lib/python3.11/site-packages/scipy/io/matlab/_mio.py\", line 39, in _open_file\n",
      "    return open(file_like, mode), True\n",
      "           ^^^^^^^^^^^^^^^^^^^^^\n",
      "\n",
      "FileNotFoundError: [Errno 2] No such file or directory: '/home/nikola/Documents/Assignment-8/data/part_A/train_data/ground_truth/IMG_10.mat'\n",
      "\n",
      "\n",
      "During handling of the above exception, another exception occurred:\n",
      "\n",
      "\n",
      "Traceback (most recent call last):\n",
      "\n",
      "  File \"/home/nikola/.local/lib/python3.11/site-packages/tensorflow/python/ops/script_ops.py\", line 268, in __call__\n",
      "    return func(device, token, args)\n",
      "           ^^^^^^^^^^^^^^^^^^^^^^^^^\n",
      "\n",
      "  File \"/home/nikola/.local/lib/python3.11/site-packages/tensorflow/python/ops/script_ops.py\", line 146, in __call__\n",
      "    outputs = self._call(device, args)\n",
      "              ^^^^^^^^^^^^^^^^^^^^^^^^\n",
      "\n",
      "  File \"/home/nikola/.local/lib/python3.11/site-packages/tensorflow/python/ops/script_ops.py\", line 153, in _call\n",
      "    ret = self._func(*args)\n",
      "          ^^^^^^^^^^^^^^^^^\n",
      "\n",
      "  File \"/home/nikola/.local/lib/python3.11/site-packages/tensorflow/python/autograph/impl/api.py\", line 643, in wrapper\n",
      "    return func(*args, **kwargs)\n",
      "           ^^^^^^^^^^^^^^^^^^^^^\n",
      "\n",
      "  File \"/tmp/ipykernel_7543/1763551795.py\", line 14, in load_image_and_density\n",
      "    density = load_density_map(gt_path)\n",
      "              ^^^^^^^^^^^^^^^^^^^^^^^^^\n",
      "\n",
      "  File \"/tmp/ipykernel_7543/1763551795.py\", line 2, in load_density_map\n",
      "    mat = scipy.io.loadmat(mat_path)\n",
      "          ^^^^^^^^^^^^^^^^^^^^^^^^^^\n",
      "\n",
      "  File \"/home/nikola/.local/lib/python3.11/site-packages/scipy/io/matlab/_mio.py\", line 233, in loadmat\n",
      "    with _open_file_context(file_name, appendmat) as f:\n",
      "\n",
      "  File \"/usr/local/lib/python3.11/contextlib.py\", line 137, in __enter__\n",
      "    return next(self.gen)\n",
      "           ^^^^^^^^^^^^^^\n",
      "\n",
      "  File \"/home/nikola/.local/lib/python3.11/site-packages/scipy/io/matlab/_mio.py\", line 17, in _open_file_context\n",
      "    f, opened = _open_file(file_like, appendmat, mode)\n",
      "                ^^^^^^^^^^^^^^^^^^^^^^^^^^^^^^^^^^^^^^\n",
      "\n",
      "  File \"/home/nikola/.local/lib/python3.11/site-packages/scipy/io/matlab/_mio.py\", line 45, in _open_file\n",
      "    return open(file_like, mode), True\n",
      "           ^^^^^^^^^^^^^^^^^^^^^\n",
      "\n",
      "FileNotFoundError: [Errno 2] No such file or directory: '/home/nikola/Documents/Assignment-8/data/part_A/train_data/ground_truth/IMG_10.mat'\n",
      "\n",
      "\n",
      "2025-07-08 00:08:30.728535: W tensorflow/core/framework/op_kernel.cc:1827] UNKNOWN: FileNotFoundError: [Errno 2] No such file or directory: '/home/nikola/Documents/Assignment-8/data/part_A/train_data/ground_truth/IMG_102.mat'\n",
      "Traceback (most recent call last):\n",
      "\n",
      "  File \"/home/nikola/.local/lib/python3.11/site-packages/scipy/io/matlab/_mio.py\", line 39, in _open_file\n",
      "    return open(file_like, mode), True\n",
      "           ^^^^^^^^^^^^^^^^^^^^^\n",
      "\n",
      "FileNotFoundError: [Errno 2] No such file or directory: '/home/nikola/Documents/Assignment-8/data/part_A/train_data/ground_truth/IMG_102.mat'\n",
      "\n",
      "\n",
      "During handling of the above exception, another exception occurred:\n",
      "\n",
      "\n",
      "Traceback (most recent call last):\n",
      "\n",
      "  File \"/home/nikola/.local/lib/python3.11/site-packages/tensorflow/python/ops/script_ops.py\", line 268, in __call__\n",
      "    return func(device, token, args)\n",
      "           ^^^^^^^^^^^^^^^^^^^^^^^^^\n",
      "\n",
      "  File \"/home/nikola/.local/lib/python3.11/site-packages/tensorflow/python/ops/script_ops.py\", line 146, in __call__\n",
      "    outputs = self._call(device, args)\n",
      "              ^^^^^^^^^^^^^^^^^^^^^^^^\n",
      "\n",
      "  File \"/home/nikola/.local/lib/python3.11/site-packages/tensorflow/python/ops/script_ops.py\", line 153, in _call\n",
      "    ret = self._func(*args)\n",
      "          ^^^^^^^^^^^^^^^^^\n",
      "\n",
      "  File \"/home/nikola/.local/lib/python3.11/site-packages/tensorflow/python/autograph/impl/api.py\", line 643, in wrapper\n",
      "    return func(*args, **kwargs)\n",
      "           ^^^^^^^^^^^^^^^^^^^^^\n",
      "\n",
      "  File \"/tmp/ipykernel_7543/1763551795.py\", line 14, in load_image_and_density\n",
      "    density = load_density_map(gt_path)\n",
      "              ^^^^^^^^^^^^^^^^^^^^^^^^^\n",
      "\n",
      "  File \"/tmp/ipykernel_7543/1763551795.py\", line 2, in load_density_map\n",
      "    mat = scipy.io.loadmat(mat_path)\n",
      "          ^^^^^^^^^^^^^^^^^^^^^^^^^^\n",
      "\n",
      "  File \"/home/nikola/.local/lib/python3.11/site-packages/scipy/io/matlab/_mio.py\", line 233, in loadmat\n",
      "    with _open_file_context(file_name, appendmat) as f:\n",
      "\n",
      "  File \"/usr/local/lib/python3.11/contextlib.py\", line 137, in __enter__\n",
      "    return next(self.gen)\n",
      "           ^^^^^^^^^^^^^^\n",
      "\n",
      "  File \"/home/nikola/.local/lib/python3.11/site-packages/scipy/io/matlab/_mio.py\", line 17, in _open_file_context\n",
      "    f, opened = _open_file(file_like, appendmat, mode)\n",
      "                ^^^^^^^^^^^^^^^^^^^^^^^^^^^^^^^^^^^^^^\n",
      "\n",
      "  File \"/home/nikola/.local/lib/python3.11/site-packages/scipy/io/matlab/_mio.py\", line 45, in _open_file\n",
      "    return open(file_like, mode), True\n",
      "           ^^^^^^^^^^^^^^^^^^^^^\n",
      "\n",
      "FileNotFoundError: [Errno 2] No such file or directory: '/home/nikola/Documents/Assignment-8/data/part_A/train_data/ground_truth/IMG_102.mat'\n",
      "\n",
      "\n",
      "2025-07-08 00:08:30.730624: W tensorflow/core/framework/op_kernel.cc:1827] UNKNOWN: FileNotFoundError: [Errno 2] No such file or directory: '/home/nikola/Documents/Assignment-8/data/part_A/train_data/ground_truth/IMG_100.mat'\n",
      "Traceback (most recent call last):\n",
      "\n",
      "  File \"/home/nikola/.local/lib/python3.11/site-packages/scipy/io/matlab/_mio.py\", line 39, in _open_file\n",
      "    return open(file_like, mode), True\n",
      "           ^^^^^^^^^^^^^^^^^^^^^\n",
      "\n",
      "FileNotFoundError: [Errno 2] No such file or directory: '/home/nikola/Documents/Assignment-8/data/part_A/train_data/ground_truth/IMG_100.mat'\n",
      "\n",
      "\n",
      "During handling of the above exception, another exception occurred:\n",
      "\n",
      "\n",
      "Traceback (most recent call last):\n",
      "\n",
      "  File \"/home/nikola/.local/lib/python3.11/site-packages/tensorflow/python/ops/script_ops.py\", line 268, in __call__\n",
      "    return func(device, token, args)\n",
      "           ^^^^^^^^^^^^^^^^^^^^^^^^^\n",
      "\n",
      "  File \"/home/nikola/.local/lib/python3.11/site-packages/tensorflow/python/ops/script_ops.py\", line 146, in __call__\n",
      "    outputs = self._call(device, args)\n",
      "              ^^^^^^^^^^^^^^^^^^^^^^^^\n",
      "\n",
      "  File \"/home/nikola/.local/lib/python3.11/site-packages/tensorflow/python/ops/script_ops.py\", line 153, in _call\n",
      "    ret = self._func(*args)\n",
      "          ^^^^^^^^^^^^^^^^^\n",
      "\n",
      "  File \"/home/nikola/.local/lib/python3.11/site-packages/tensorflow/python/autograph/impl/api.py\", line 643, in wrapper\n",
      "    return func(*args, **kwargs)\n",
      "           ^^^^^^^^^^^^^^^^^^^^^\n",
      "\n",
      "  File \"/tmp/ipykernel_7543/1763551795.py\", line 14, in load_image_and_density\n",
      "    density = load_density_map(gt_path)\n",
      "              ^^^^^^^^^^^^^^^^^^^^^^^^^\n",
      "\n",
      "  File \"/tmp/ipykernel_7543/1763551795.py\", line 2, in load_density_map\n",
      "    mat = scipy.io.loadmat(mat_path)\n",
      "          ^^^^^^^^^^^^^^^^^^^^^^^^^^\n",
      "\n",
      "  File \"/home/nikola/.local/lib/python3.11/site-packages/scipy/io/matlab/_mio.py\", line 233, in loadmat\n",
      "    with _open_file_context(file_name, appendmat) as f:\n",
      "\n",
      "  File \"/usr/local/lib/python3.11/contextlib.py\", line 137, in __enter__\n",
      "    return next(self.gen)\n",
      "           ^^^^^^^^^^^^^^\n",
      "\n",
      "  File \"/home/nikola/.local/lib/python3.11/site-packages/scipy/io/matlab/_mio.py\", line 17, in _open_file_context\n",
      "    f, opened = _open_file(file_like, appendmat, mode)\n",
      "                ^^^^^^^^^^^^^^^^^^^^^^^^^^^^^^^^^^^^^^\n",
      "\n",
      "  File \"/home/nikola/.local/lib/python3.11/site-packages/scipy/io/matlab/_mio.py\", line 45, in _open_file\n",
      "    return open(file_like, mode), True\n",
      "           ^^^^^^^^^^^^^^^^^^^^^\n",
      "\n",
      "FileNotFoundError: [Errno 2] No such file or directory: '/home/nikola/Documents/Assignment-8/data/part_A/train_data/ground_truth/IMG_100.mat'\n",
      "\n",
      "\n",
      "2025-07-08 00:08:30.730983: W tensorflow/core/framework/op_kernel.cc:1827] UNKNOWN: FileNotFoundError: [Errno 2] No such file or directory: '/home/nikola/Documents/Assignment-8/data/part_A/train_data/ground_truth/IMG_101.mat'\n",
      "Traceback (most recent call last):\n",
      "\n",
      "  File \"/home/nikola/.local/lib/python3.11/site-packages/scipy/io/matlab/_mio.py\", line 39, in _open_file\n",
      "    return open(file_like, mode), True\n",
      "           ^^^^^^^^^^^^^^^^^^^^^\n",
      "\n",
      "FileNotFoundError: [Errno 2] No such file or directory: '/home/nikola/Documents/Assignment-8/data/part_A/train_data/ground_truth/IMG_101.mat'\n",
      "\n",
      "\n",
      "During handling of the above exception, another exception occurred:\n",
      "\n",
      "\n",
      "Traceback (most recent call last):\n",
      "\n",
      "  File \"/home/nikola/.local/lib/python3.11/site-packages/tensorflow/python/ops/script_ops.py\", line 268, in __call__\n",
      "    return func(device, token, args)\n",
      "           ^^^^^^^^^^^^^^^^^^^^^^^^^\n",
      "\n",
      "  File \"/home/nikola/.local/lib/python3.11/site-packages/tensorflow/python/ops/script_ops.py\", line 146, in __call__\n",
      "    outputs = self._call(device, args)\n",
      "              ^^^^^^^^^^^^^^^^^^^^^^^^\n",
      "\n",
      "  File \"/home/nikola/.local/lib/python3.11/site-packages/tensorflow/python/ops/script_ops.py\", line 153, in _call\n",
      "    ret = self._func(*args)\n",
      "          ^^^^^^^^^^^^^^^^^\n",
      "\n",
      "  File \"/home/nikola/.local/lib/python3.11/site-packages/tensorflow/python/autograph/impl/api.py\", line 643, in wrapper\n",
      "    return func(*args, **kwargs)\n",
      "           ^^^^^^^^^^^^^^^^^^^^^\n",
      "\n",
      "  File \"/tmp/ipykernel_7543/1763551795.py\", line 14, in load_image_and_density\n",
      "    density = load_density_map(gt_path)\n",
      "              ^^^^^^^^^^^^^^^^^^^^^^^^^\n",
      "\n",
      "  File \"/tmp/ipykernel_7543/1763551795.py\", line 2, in load_density_map\n",
      "    mat = scipy.io.loadmat(mat_path)\n",
      "          ^^^^^^^^^^^^^^^^^^^^^^^^^^\n",
      "\n",
      "  File \"/home/nikola/.local/lib/python3.11/site-packages/scipy/io/matlab/_mio.py\", line 233, in loadmat\n",
      "    with _open_file_context(file_name, appendmat) as f:\n",
      "\n",
      "  File \"/usr/local/lib/python3.11/contextlib.py\", line 137, in __enter__\n",
      "    return next(self.gen)\n",
      "           ^^^^^^^^^^^^^^\n",
      "\n",
      "  File \"/home/nikola/.local/lib/python3.11/site-packages/scipy/io/matlab/_mio.py\", line 17, in _open_file_context\n",
      "    f, opened = _open_file(file_like, appendmat, mode)\n",
      "                ^^^^^^^^^^^^^^^^^^^^^^^^^^^^^^^^^^^^^^\n",
      "\n",
      "  File \"/home/nikola/.local/lib/python3.11/site-packages/scipy/io/matlab/_mio.py\", line 45, in _open_file\n",
      "    return open(file_like, mode), True\n",
      "           ^^^^^^^^^^^^^^^^^^^^^\n",
      "\n",
      "FileNotFoundError: [Errno 2] No such file or directory: '/home/nikola/Documents/Assignment-8/data/part_A/train_data/ground_truth/IMG_101.mat'\n",
      "\n",
      "\n",
      "2025-07-08 00:08:30.731485: W tensorflow/core/framework/op_kernel.cc:1827] UNKNOWN: FileNotFoundError: [Errno 2] No such file or directory: '/home/nikola/Documents/Assignment-8/data/part_A/train_data/ground_truth/IMG_103.mat'\n",
      "Traceback (most recent call last):\n",
      "\n",
      "  File \"/home/nikola/.local/lib/python3.11/site-packages/scipy/io/matlab/_mio.py\", line 39, in _open_file\n",
      "    return open(file_like, mode), True\n",
      "           ^^^^^^^^^^^^^^^^^^^^^\n",
      "\n",
      "FileNotFoundError: [Errno 2] No such file or directory: '/home/nikola/Documents/Assignment-8/data/part_A/train_data/ground_truth/IMG_103.mat'\n",
      "\n",
      "\n",
      "During handling of the above exception, another exception occurred:\n",
      "\n",
      "\n",
      "Traceback (most recent call last):\n",
      "\n",
      "  File \"/home/nikola/.local/lib/python3.11/site-packages/tensorflow/python/ops/script_ops.py\", line 268, in __call__\n",
      "    return func(device, token, args)\n",
      "           ^^^^^^^^^^^^^^^^^^^^^^^^^\n",
      "\n",
      "  File \"/home/nikola/.local/lib/python3.11/site-packages/tensorflow/python/ops/script_ops.py\", line 146, in __call__\n",
      "    outputs = self._call(device, args)\n",
      "              ^^^^^^^^^^^^^^^^^^^^^^^^\n",
      "\n",
      "  File \"/home/nikola/.local/lib/python3.11/site-packages/tensorflow/python/ops/script_ops.py\", line 153, in _call\n",
      "    ret = self._func(*args)\n",
      "          ^^^^^^^^^^^^^^^^^\n",
      "\n",
      "  File \"/home/nikola/.local/lib/python3.11/site-packages/tensorflow/python/autograph/impl/api.py\", line 643, in wrapper\n",
      "    return func(*args, **kwargs)\n",
      "           ^^^^^^^^^^^^^^^^^^^^^\n",
      "\n",
      "  File \"/tmp/ipykernel_7543/1763551795.py\", line 14, in load_image_and_density\n",
      "    density = load_density_map(gt_path)\n",
      "              ^^^^^^^^^^^^^^^^^^^^^^^^^\n",
      "\n",
      "  File \"/tmp/ipykernel_7543/1763551795.py\", line 2, in load_density_map\n",
      "    mat = scipy.io.loadmat(mat_path)\n",
      "          ^^^^^^^^^^^^^^^^^^^^^^^^^^\n",
      "\n",
      "  File \"/home/nikola/.local/lib/python3.11/site-packages/scipy/io/matlab/_mio.py\", line 233, in loadmat\n",
      "    with _open_file_context(file_name, appendmat) as f:\n",
      "\n",
      "  File \"/usr/local/lib/python3.11/contextlib.py\", line 137, in __enter__\n",
      "    return next(self.gen)\n",
      "           ^^^^^^^^^^^^^^\n",
      "\n",
      "  File \"/home/nikola/.local/lib/python3.11/site-packages/scipy/io/matlab/_mio.py\", line 17, in _open_file_context\n",
      "    f, opened = _open_file(file_like, appendmat, mode)\n",
      "                ^^^^^^^^^^^^^^^^^^^^^^^^^^^^^^^^^^^^^^\n",
      "\n",
      "  File \"/home/nikola/.local/lib/python3.11/site-packages/scipy/io/matlab/_mio.py\", line 45, in _open_file\n",
      "    return open(file_like, mode), True\n",
      "           ^^^^^^^^^^^^^^^^^^^^^\n",
      "\n",
      "FileNotFoundError: [Errno 2] No such file or directory: '/home/nikola/Documents/Assignment-8/data/part_A/train_data/ground_truth/IMG_103.mat'\n",
      "\n",
      "\n",
      "2025-07-08 00:08:30.731951: W tensorflow/core/framework/op_kernel.cc:1827] UNKNOWN: FileNotFoundError: [Errno 2] No such file or directory: '/home/nikola/Documents/Assignment-8/data/part_A/train_data/ground_truth/IMG_1.mat'\n",
      "Traceback (most recent call last):\n",
      "\n",
      "  File \"/home/nikola/.local/lib/python3.11/site-packages/scipy/io/matlab/_mio.py\", line 39, in _open_file\n",
      "    return open(file_like, mode), True\n",
      "           ^^^^^^^^^^^^^^^^^^^^^\n",
      "\n",
      "FileNotFoundError: [Errno 2] No such file or directory: '/home/nikola/Documents/Assignment-8/data/part_A/train_data/ground_truth/IMG_1.mat'\n",
      "\n",
      "\n",
      "During handling of the above exception, another exception occurred:\n",
      "\n",
      "\n",
      "Traceback (most recent call last):\n",
      "\n",
      "  File \"/home/nikola/.local/lib/python3.11/site-packages/tensorflow/python/ops/script_ops.py\", line 268, in __call__\n",
      "    return func(device, token, args)\n",
      "           ^^^^^^^^^^^^^^^^^^^^^^^^^\n",
      "\n",
      "  File \"/home/nikola/.local/lib/python3.11/site-packages/tensorflow/python/ops/script_ops.py\", line 146, in __call__\n",
      "    outputs = self._call(device, args)\n",
      "              ^^^^^^^^^^^^^^^^^^^^^^^^\n",
      "\n",
      "  File \"/home/nikola/.local/lib/python3.11/site-packages/tensorflow/python/ops/script_ops.py\", line 153, in _call\n",
      "    ret = self._func(*args)\n",
      "          ^^^^^^^^^^^^^^^^^\n",
      "\n",
      "  File \"/home/nikola/.local/lib/python3.11/site-packages/tensorflow/python/autograph/impl/api.py\", line 643, in wrapper\n",
      "    return func(*args, **kwargs)\n",
      "           ^^^^^^^^^^^^^^^^^^^^^\n",
      "\n",
      "  File \"/tmp/ipykernel_7543/1763551795.py\", line 14, in load_image_and_density\n",
      "    density = load_density_map(gt_path)\n",
      "              ^^^^^^^^^^^^^^^^^^^^^^^^^\n",
      "\n",
      "  File \"/tmp/ipykernel_7543/1763551795.py\", line 2, in load_density_map\n",
      "    mat = scipy.io.loadmat(mat_path)\n",
      "          ^^^^^^^^^^^^^^^^^^^^^^^^^^\n",
      "\n",
      "  File \"/home/nikola/.local/lib/python3.11/site-packages/scipy/io/matlab/_mio.py\", line 233, in loadmat\n",
      "    with _open_file_context(file_name, appendmat) as f:\n",
      "\n",
      "  File \"/usr/local/lib/python3.11/contextlib.py\", line 137, in __enter__\n",
      "    return next(self.gen)\n",
      "           ^^^^^^^^^^^^^^\n",
      "\n",
      "  File \"/home/nikola/.local/lib/python3.11/site-packages/scipy/io/matlab/_mio.py\", line 17, in _open_file_context\n",
      "    f, opened = _open_file(file_like, appendmat, mode)\n",
      "                ^^^^^^^^^^^^^^^^^^^^^^^^^^^^^^^^^^^^^^\n",
      "\n",
      "  File \"/home/nikola/.local/lib/python3.11/site-packages/scipy/io/matlab/_mio.py\", line 45, in _open_file\n",
      "    return open(file_like, mode), True\n",
      "           ^^^^^^^^^^^^^^^^^^^^^\n",
      "\n",
      "FileNotFoundError: [Errno 2] No such file or directory: '/home/nikola/Documents/Assignment-8/data/part_A/train_data/ground_truth/IMG_1.mat'\n",
      "\n",
      "\n",
      "2025-07-08 00:08:30.733083: W tensorflow/core/framework/op_kernel.cc:1827] UNKNOWN: FileNotFoundError: [Errno 2] No such file or directory: '/home/nikola/Documents/Assignment-8/data/part_A/train_data/ground_truth/IMG_104.mat'\n",
      "Traceback (most recent call last):\n",
      "\n",
      "  File \"/home/nikola/.local/lib/python3.11/site-packages/scipy/io/matlab/_mio.py\", line 39, in _open_file\n",
      "    return open(file_like, mode), True\n",
      "           ^^^^^^^^^^^^^^^^^^^^^\n",
      "\n",
      "FileNotFoundError: [Errno 2] No such file or directory: '/home/nikola/Documents/Assignment-8/data/part_A/train_data/ground_truth/IMG_104.mat'\n",
      "\n",
      "\n",
      "During handling of the above exception, another exception occurred:\n",
      "\n",
      "\n",
      "Traceback (most recent call last):\n",
      "\n",
      "  File \"/home/nikola/.local/lib/python3.11/site-packages/tensorflow/python/ops/script_ops.py\", line 268, in __call__\n",
      "    return func(device, token, args)\n",
      "           ^^^^^^^^^^^^^^^^^^^^^^^^^\n",
      "\n",
      "  File \"/home/nikola/.local/lib/python3.11/site-packages/tensorflow/python/ops/script_ops.py\", line 146, in __call__\n",
      "    outputs = self._call(device, args)\n",
      "              ^^^^^^^^^^^^^^^^^^^^^^^^\n",
      "\n",
      "  File \"/home/nikola/.local/lib/python3.11/site-packages/tensorflow/python/ops/script_ops.py\", line 153, in _call\n",
      "    ret = self._func(*args)\n",
      "          ^^^^^^^^^^^^^^^^^\n",
      "\n",
      "  File \"/home/nikola/.local/lib/python3.11/site-packages/tensorflow/python/autograph/impl/api.py\", line 643, in wrapper\n",
      "    return func(*args, **kwargs)\n",
      "           ^^^^^^^^^^^^^^^^^^^^^\n",
      "\n",
      "  File \"/tmp/ipykernel_7543/1763551795.py\", line 14, in load_image_and_density\n",
      "    density = load_density_map(gt_path)\n",
      "              ^^^^^^^^^^^^^^^^^^^^^^^^^\n",
      "\n",
      "  File \"/tmp/ipykernel_7543/1763551795.py\", line 2, in load_density_map\n",
      "    mat = scipy.io.loadmat(mat_path)\n",
      "          ^^^^^^^^^^^^^^^^^^^^^^^^^^\n",
      "\n",
      "  File \"/home/nikola/.local/lib/python3.11/site-packages/scipy/io/matlab/_mio.py\", line 233, in loadmat\n",
      "    with _open_file_context(file_name, appendmat) as f:\n",
      "\n",
      "  File \"/usr/local/lib/python3.11/contextlib.py\", line 137, in __enter__\n",
      "    return next(self.gen)\n",
      "           ^^^^^^^^^^^^^^\n",
      "\n",
      "  File \"/home/nikola/.local/lib/python3.11/site-packages/scipy/io/matlab/_mio.py\", line 17, in _open_file_context\n",
      "    f, opened = _open_file(file_like, appendmat, mode)\n",
      "                ^^^^^^^^^^^^^^^^^^^^^^^^^^^^^^^^^^^^^^\n",
      "\n",
      "  File \"/home/nikola/.local/lib/python3.11/site-packages/scipy/io/matlab/_mio.py\", line 45, in _open_file\n",
      "    return open(file_like, mode), True\n",
      "           ^^^^^^^^^^^^^^^^^^^^^\n",
      "\n",
      "FileNotFoundError: [Errno 2] No such file or directory: '/home/nikola/Documents/Assignment-8/data/part_A/train_data/ground_truth/IMG_104.mat'\n",
      "\n",
      "\n",
      "2025-07-08 00:08:30.733641: W tensorflow/core/framework/op_kernel.cc:1827] UNKNOWN: FileNotFoundError: [Errno 2] No such file or directory: '/home/nikola/Documents/Assignment-8/data/part_A/train_data/ground_truth/IMG_105.mat'\n",
      "Traceback (most recent call last):\n",
      "\n",
      "  File \"/home/nikola/.local/lib/python3.11/site-packages/scipy/io/matlab/_mio.py\", line 39, in _open_file\n",
      "    return open(file_like, mode), True\n",
      "           ^^^^^^^^^^^^^^^^^^^^^\n",
      "\n",
      "FileNotFoundError: [Errno 2] No such file or directory: '/home/nikola/Documents/Assignment-8/data/part_A/train_data/ground_truth/IMG_105.mat'\n",
      "\n",
      "\n",
      "During handling of the above exception, another exception occurred:\n",
      "\n",
      "\n",
      "Traceback (most recent call last):\n",
      "\n",
      "  File \"/home/nikola/.local/lib/python3.11/site-packages/tensorflow/python/ops/script_ops.py\", line 268, in __call__\n",
      "    return func(device, token, args)\n",
      "           ^^^^^^^^^^^^^^^^^^^^^^^^^\n",
      "\n",
      "  File \"/home/nikola/.local/lib/python3.11/site-packages/tensorflow/python/ops/script_ops.py\", line 146, in __call__\n",
      "    outputs = self._call(device, args)\n",
      "              ^^^^^^^^^^^^^^^^^^^^^^^^\n",
      "\n",
      "  File \"/home/nikola/.local/lib/python3.11/site-packages/tensorflow/python/ops/script_ops.py\", line 153, in _call\n",
      "    ret = self._func(*args)\n",
      "          ^^^^^^^^^^^^^^^^^\n",
      "\n",
      "  File \"/home/nikola/.local/lib/python3.11/site-packages/tensorflow/python/autograph/impl/api.py\", line 643, in wrapper\n",
      "    return func(*args, **kwargs)\n",
      "           ^^^^^^^^^^^^^^^^^^^^^\n",
      "\n",
      "  File \"/tmp/ipykernel_7543/1763551795.py\", line 14, in load_image_and_density\n",
      "    density = load_density_map(gt_path)\n",
      "              ^^^^^^^^^^^^^^^^^^^^^^^^^\n",
      "\n",
      "  File \"/tmp/ipykernel_7543/1763551795.py\", line 2, in load_density_map\n",
      "    mat = scipy.io.loadmat(mat_path)\n",
      "          ^^^^^^^^^^^^^^^^^^^^^^^^^^\n",
      "\n",
      "  File \"/home/nikola/.local/lib/python3.11/site-packages/scipy/io/matlab/_mio.py\", line 233, in loadmat\n",
      "    with _open_file_context(file_name, appendmat) as f:\n",
      "\n",
      "  File \"/usr/local/lib/python3.11/contextlib.py\", line 137, in __enter__\n",
      "    return next(self.gen)\n",
      "           ^^^^^^^^^^^^^^\n",
      "\n",
      "  File \"/home/nikola/.local/lib/python3.11/site-packages/scipy/io/matlab/_mio.py\", line 17, in _open_file_context\n",
      "    f, opened = _open_file(file_like, appendmat, mode)\n",
      "                ^^^^^^^^^^^^^^^^^^^^^^^^^^^^^^^^^^^^^^\n",
      "\n",
      "  File \"/home/nikola/.local/lib/python3.11/site-packages/scipy/io/matlab/_mio.py\", line 45, in _open_file\n",
      "    return open(file_like, mode), True\n",
      "           ^^^^^^^^^^^^^^^^^^^^^\n",
      "\n",
      "FileNotFoundError: [Errno 2] No such file or directory: '/home/nikola/Documents/Assignment-8/data/part_A/train_data/ground_truth/IMG_105.mat'\n",
      "\n",
      "\n",
      "2025-07-08 00:08:30.764174: W tensorflow/core/framework/op_kernel.cc:1827] UNKNOWN: FileNotFoundError: [Errno 2] No such file or directory: '/home/nikola/Documents/Assignment-8/data/part_A/train_data/ground_truth/IMG_106.mat'\n",
      "Traceback (most recent call last):\n",
      "\n",
      "  File \"/home/nikola/.local/lib/python3.11/site-packages/scipy/io/matlab/_mio.py\", line 39, in _open_file\n",
      "    return open(file_like, mode), True\n",
      "           ^^^^^^^^^^^^^^^^^^^^^\n",
      "\n",
      "FileNotFoundError: [Errno 2] No such file or directory: '/home/nikola/Documents/Assignment-8/data/part_A/train_data/ground_truth/IMG_106.mat'\n",
      "\n",
      "\n",
      "During handling of the above exception, another exception occurred:\n",
      "\n",
      "\n",
      "Traceback (most recent call last):\n",
      "\n",
      "  File \"/home/nikola/.local/lib/python3.11/site-packages/tensorflow/python/ops/script_ops.py\", line 268, in __call__\n",
      "    return func(device, token, args)\n",
      "           ^^^^^^^^^^^^^^^^^^^^^^^^^\n",
      "\n",
      "  File \"/home/nikola/.local/lib/python3.11/site-packages/tensorflow/python/ops/script_ops.py\", line 146, in __call__\n",
      "    outputs = self._call(device, args)\n",
      "              ^^^^^^^^^^^^^^^^^^^^^^^^\n",
      "\n",
      "  File \"/home/nikola/.local/lib/python3.11/site-packages/tensorflow/python/ops/script_ops.py\", line 153, in _call\n",
      "    ret = self._func(*args)\n",
      "          ^^^^^^^^^^^^^^^^^\n",
      "\n",
      "  File \"/home/nikola/.local/lib/python3.11/site-packages/tensorflow/python/autograph/impl/api.py\", line 643, in wrapper\n",
      "    return func(*args, **kwargs)\n",
      "           ^^^^^^^^^^^^^^^^^^^^^\n",
      "\n",
      "  File \"/tmp/ipykernel_7543/1763551795.py\", line 14, in load_image_and_density\n",
      "    density = load_density_map(gt_path)\n",
      "              ^^^^^^^^^^^^^^^^^^^^^^^^^\n",
      "\n",
      "  File \"/tmp/ipykernel_7543/1763551795.py\", line 2, in load_density_map\n",
      "    mat = scipy.io.loadmat(mat_path)\n",
      "          ^^^^^^^^^^^^^^^^^^^^^^^^^^\n",
      "\n",
      "  File \"/home/nikola/.local/lib/python3.11/site-packages/scipy/io/matlab/_mio.py\", line 233, in loadmat\n",
      "    with _open_file_context(file_name, appendmat) as f:\n",
      "\n",
      "  File \"/usr/local/lib/python3.11/contextlib.py\", line 137, in __enter__\n",
      "    return next(self.gen)\n",
      "           ^^^^^^^^^^^^^^\n",
      "\n",
      "  File \"/home/nikola/.local/lib/python3.11/site-packages/scipy/io/matlab/_mio.py\", line 17, in _open_file_context\n",
      "    f, opened = _open_file(file_like, appendmat, mode)\n",
      "                ^^^^^^^^^^^^^^^^^^^^^^^^^^^^^^^^^^^^^^\n",
      "\n",
      "  File \"/home/nikola/.local/lib/python3.11/site-packages/scipy/io/matlab/_mio.py\", line 45, in _open_file\n",
      "    return open(file_like, mode), True\n",
      "           ^^^^^^^^^^^^^^^^^^^^^\n",
      "\n",
      "FileNotFoundError: [Errno 2] No such file or directory: '/home/nikola/Documents/Assignment-8/data/part_A/train_data/ground_truth/IMG_106.mat'\n",
      "\n",
      "\n",
      "2025-07-08 00:08:30.764906: W tensorflow/core/framework/op_kernel.cc:1827] UNKNOWN: FileNotFoundError: [Errno 2] No such file or directory: '/home/nikola/Documents/Assignment-8/data/part_A/train_data/ground_truth/IMG_108.mat'\n",
      "Traceback (most recent call last):\n",
      "\n",
      "  File \"/home/nikola/.local/lib/python3.11/site-packages/scipy/io/matlab/_mio.py\", line 39, in _open_file\n",
      "    return open(file_like, mode), True\n",
      "           ^^^^^^^^^^^^^^^^^^^^^\n",
      "\n",
      "FileNotFoundError: [Errno 2] No such file or directory: '/home/nikola/Documents/Assignment-8/data/part_A/train_data/ground_truth/IMG_108.mat'\n",
      "\n",
      "\n",
      "During handling of the above exception, another exception occurred:\n",
      "\n",
      "\n",
      "Traceback (most recent call last):\n",
      "\n",
      "  File \"/home/nikola/.local/lib/python3.11/site-packages/tensorflow/python/ops/script_ops.py\", line 268, in __call__\n",
      "    return func(device, token, args)\n",
      "           ^^^^^^^^^^^^^^^^^^^^^^^^^\n",
      "\n",
      "  File \"/home/nikola/.local/lib/python3.11/site-packages/tensorflow/python/ops/script_ops.py\", line 146, in __call__\n",
      "    outputs = self._call(device, args)\n",
      "              ^^^^^^^^^^^^^^^^^^^^^^^^\n",
      "\n",
      "  File \"/home/nikola/.local/lib/python3.11/site-packages/tensorflow/python/ops/script_ops.py\", line 153, in _call\n",
      "    ret = self._func(*args)\n",
      "          ^^^^^^^^^^^^^^^^^\n",
      "\n",
      "  File \"/home/nikola/.local/lib/python3.11/site-packages/tensorflow/python/autograph/impl/api.py\", line 643, in wrapper\n",
      "    return func(*args, **kwargs)\n",
      "           ^^^^^^^^^^^^^^^^^^^^^\n",
      "\n",
      "  File \"/tmp/ipykernel_7543/1763551795.py\", line 14, in load_image_and_density\n",
      "    density = load_density_map(gt_path)\n",
      "              ^^^^^^^^^^^^^^^^^^^^^^^^^\n",
      "\n",
      "  File \"/tmp/ipykernel_7543/1763551795.py\", line 2, in load_density_map\n",
      "    mat = scipy.io.loadmat(mat_path)\n",
      "          ^^^^^^^^^^^^^^^^^^^^^^^^^^\n",
      "\n",
      "  File \"/home/nikola/.local/lib/python3.11/site-packages/scipy/io/matlab/_mio.py\", line 233, in loadmat\n",
      "    with _open_file_context(file_name, appendmat) as f:\n",
      "\n",
      "  File \"/usr/local/lib/python3.11/contextlib.py\", line 137, in __enter__\n",
      "    return next(self.gen)\n",
      "           ^^^^^^^^^^^^^^\n",
      "\n",
      "  File \"/home/nikola/.local/lib/python3.11/site-packages/scipy/io/matlab/_mio.py\", line 17, in _open_file_context\n",
      "    f, opened = _open_file(file_like, appendmat, mode)\n",
      "                ^^^^^^^^^^^^^^^^^^^^^^^^^^^^^^^^^^^^^^\n",
      "\n",
      "  File \"/home/nikola/.local/lib/python3.11/site-packages/scipy/io/matlab/_mio.py\", line 45, in _open_file\n",
      "    return open(file_like, mode), True\n",
      "           ^^^^^^^^^^^^^^^^^^^^^\n",
      "\n",
      "FileNotFoundError: [Errno 2] No such file or directory: '/home/nikola/Documents/Assignment-8/data/part_A/train_data/ground_truth/IMG_108.mat'\n",
      "\n",
      "\n",
      "2025-07-08 00:08:30.776023: W tensorflow/core/framework/op_kernel.cc:1827] UNKNOWN: FileNotFoundError: [Errno 2] No such file or directory: '/home/nikola/Documents/Assignment-8/data/part_A/train_data/ground_truth/IMG_107.mat'\n",
      "Traceback (most recent call last):\n",
      "\n",
      "  File \"/home/nikola/.local/lib/python3.11/site-packages/scipy/io/matlab/_mio.py\", line 39, in _open_file\n",
      "    return open(file_like, mode), True\n",
      "           ^^^^^^^^^^^^^^^^^^^^^\n",
      "\n",
      "FileNotFoundError: [Errno 2] No such file or directory: '/home/nikola/Documents/Assignment-8/data/part_A/train_data/ground_truth/IMG_107.mat'\n",
      "\n",
      "\n",
      "During handling of the above exception, another exception occurred:\n",
      "\n",
      "\n",
      "Traceback (most recent call last):\n",
      "\n",
      "  File \"/home/nikola/.local/lib/python3.11/site-packages/tensorflow/python/ops/script_ops.py\", line 268, in __call__\n",
      "    return func(device, token, args)\n",
      "           ^^^^^^^^^^^^^^^^^^^^^^^^^\n",
      "\n",
      "  File \"/home/nikola/.local/lib/python3.11/site-packages/tensorflow/python/ops/script_ops.py\", line 146, in __call__\n",
      "    outputs = self._call(device, args)\n",
      "              ^^^^^^^^^^^^^^^^^^^^^^^^\n",
      "\n",
      "  File \"/home/nikola/.local/lib/python3.11/site-packages/tensorflow/python/ops/script_ops.py\", line 153, in _call\n",
      "    ret = self._func(*args)\n",
      "          ^^^^^^^^^^^^^^^^^\n",
      "\n",
      "  File \"/home/nikola/.local/lib/python3.11/site-packages/tensorflow/python/autograph/impl/api.py\", line 643, in wrapper\n",
      "    return func(*args, **kwargs)\n",
      "           ^^^^^^^^^^^^^^^^^^^^^\n",
      "\n",
      "  File \"/tmp/ipykernel_7543/1763551795.py\", line 14, in load_image_and_density\n",
      "    density = load_density_map(gt_path)\n",
      "              ^^^^^^^^^^^^^^^^^^^^^^^^^\n",
      "\n",
      "  File \"/tmp/ipykernel_7543/1763551795.py\", line 2, in load_density_map\n",
      "    mat = scipy.io.loadmat(mat_path)\n",
      "          ^^^^^^^^^^^^^^^^^^^^^^^^^^\n",
      "\n",
      "  File \"/home/nikola/.local/lib/python3.11/site-packages/scipy/io/matlab/_mio.py\", line 233, in loadmat\n",
      "    with _open_file_context(file_name, appendmat) as f:\n",
      "\n",
      "  File \"/usr/local/lib/python3.11/contextlib.py\", line 137, in __enter__\n",
      "    return next(self.gen)\n",
      "           ^^^^^^^^^^^^^^\n",
      "\n",
      "  File \"/home/nikola/.local/lib/python3.11/site-packages/scipy/io/matlab/_mio.py\", line 17, in _open_file_context\n",
      "    f, opened = _open_file(file_like, appendmat, mode)\n",
      "                ^^^^^^^^^^^^^^^^^^^^^^^^^^^^^^^^^^^^^^\n",
      "\n",
      "  File \"/home/nikola/.local/lib/python3.11/site-packages/scipy/io/matlab/_mio.py\", line 45, in _open_file\n",
      "    return open(file_like, mode), True\n",
      "           ^^^^^^^^^^^^^^^^^^^^^\n",
      "\n",
      "FileNotFoundError: [Errno 2] No such file or directory: '/home/nikola/Documents/Assignment-8/data/part_A/train_data/ground_truth/IMG_107.mat'\n",
      "\n",
      "\n"
     ]
    },
    {
     "ename": "UnknownError",
     "evalue": "{{function_node __wrapped__IteratorGetNext_output_types_2_device_/job:localhost/replica:0/task:0/device:CPU:0}} FileNotFoundError: [Errno 2] No such file or directory: '/home/nikola/Documents/Assignment-8/data/part_A/train_data/ground_truth/IMG_1.mat'\nTraceback (most recent call last):\n\n  File \"/home/nikola/.local/lib/python3.11/site-packages/scipy/io/matlab/_mio.py\", line 39, in _open_file\n    return open(file_like, mode), True\n           ^^^^^^^^^^^^^^^^^^^^^\n\nFileNotFoundError: [Errno 2] No such file or directory: '/home/nikola/Documents/Assignment-8/data/part_A/train_data/ground_truth/IMG_1.mat'\n\n\nDuring handling of the above exception, another exception occurred:\n\n\nTraceback (most recent call last):\n\n  File \"/home/nikola/.local/lib/python3.11/site-packages/tensorflow/python/ops/script_ops.py\", line 268, in __call__\n    return func(device, token, args)\n           ^^^^^^^^^^^^^^^^^^^^^^^^^\n\n  File \"/home/nikola/.local/lib/python3.11/site-packages/tensorflow/python/ops/script_ops.py\", line 146, in __call__\n    outputs = self._call(device, args)\n              ^^^^^^^^^^^^^^^^^^^^^^^^\n\n  File \"/home/nikola/.local/lib/python3.11/site-packages/tensorflow/python/ops/script_ops.py\", line 153, in _call\n    ret = self._func(*args)\n          ^^^^^^^^^^^^^^^^^\n\n  File \"/home/nikola/.local/lib/python3.11/site-packages/tensorflow/python/autograph/impl/api.py\", line 643, in wrapper\n    return func(*args, **kwargs)\n           ^^^^^^^^^^^^^^^^^^^^^\n\n  File \"/tmp/ipykernel_7543/1763551795.py\", line 14, in load_image_and_density\n    density = load_density_map(gt_path)\n              ^^^^^^^^^^^^^^^^^^^^^^^^^\n\n  File \"/tmp/ipykernel_7543/1763551795.py\", line 2, in load_density_map\n    mat = scipy.io.loadmat(mat_path)\n          ^^^^^^^^^^^^^^^^^^^^^^^^^^\n\n  File \"/home/nikola/.local/lib/python3.11/site-packages/scipy/io/matlab/_mio.py\", line 233, in loadmat\n    with _open_file_context(file_name, appendmat) as f:\n\n  File \"/usr/local/lib/python3.11/contextlib.py\", line 137, in __enter__\n    return next(self.gen)\n           ^^^^^^^^^^^^^^\n\n  File \"/home/nikola/.local/lib/python3.11/site-packages/scipy/io/matlab/_mio.py\", line 17, in _open_file_context\n    f, opened = _open_file(file_like, appendmat, mode)\n                ^^^^^^^^^^^^^^^^^^^^^^^^^^^^^^^^^^^^^^\n\n  File \"/home/nikola/.local/lib/python3.11/site-packages/scipy/io/matlab/_mio.py\", line 45, in _open_file\n    return open(file_like, mode), True\n           ^^^^^^^^^^^^^^^^^^^^^\n\nFileNotFoundError: [Errno 2] No such file or directory: '/home/nikola/Documents/Assignment-8/data/part_A/train_data/ground_truth/IMG_1.mat'\n\n\n\t [[{{node EagerPyFunc}}]] [Op:IteratorGetNext] name: ",
     "output_type": "error",
     "traceback": [
      "\u001b[31m---------------------------------------------------------------------------\u001b[39m",
      "\u001b[31mUnknownError\u001b[39m                              Traceback (most recent call last)",
      "\u001b[36mCell\u001b[39m\u001b[36m \u001b[39m\u001b[32mIn[30]\u001b[39m\u001b[32m, line 1\u001b[39m\n\u001b[32m----> \u001b[39m\u001b[32m1\u001b[39m \u001b[38;5;28;43;01mfor\u001b[39;49;00m\u001b[43m \u001b[49m\u001b[43mimg_batch\u001b[49m\u001b[43m,\u001b[49m\u001b[43m \u001b[49m\u001b[43mgt_batch\u001b[49m\u001b[43m \u001b[49m\u001b[38;5;129;43;01min\u001b[39;49;00m\u001b[43m \u001b[49m\u001b[43mtrain_ds\u001b[49m\u001b[43m.\u001b[49m\u001b[43mtake\u001b[49m\u001b[43m(\u001b[49m\u001b[32;43m1\u001b[39;49m\u001b[43m)\u001b[49m\u001b[43m:\u001b[49m\n\u001b[32m      2\u001b[39m \u001b[43m    \u001b[49m\u001b[38;5;28;43mprint\u001b[39;49m\u001b[43m(\u001b[49m\u001b[33;43m\"\u001b[39;49m\u001b[33;43mImage batch shape:\u001b[39;49m\u001b[33;43m\"\u001b[39;49m\u001b[43m,\u001b[49m\u001b[43m \u001b[49m\u001b[43mimg_batch\u001b[49m\u001b[43m.\u001b[49m\u001b[43mshape\u001b[49m\u001b[43m,\u001b[49m\u001b[43m \u001b[49m\u001b[43mimg_batch\u001b[49m\u001b[43m.\u001b[49m\u001b[43mdtype\u001b[49m\u001b[43m)\u001b[49m\n\u001b[32m      3\u001b[39m \u001b[43m    \u001b[49m\u001b[38;5;28;43mprint\u001b[39;49m\u001b[43m(\u001b[49m\u001b[33;43m\"\u001b[39;49m\u001b[33;43mGT batch shape:\u001b[39;49m\u001b[33;43m\"\u001b[39;49m\u001b[43m,\u001b[49m\u001b[43m \u001b[49m\u001b[43mgt_batch\u001b[49m\u001b[43m.\u001b[49m\u001b[43mshape\u001b[49m\u001b[43m,\u001b[49m\u001b[43m \u001b[49m\u001b[43mgt_batch\u001b[49m\u001b[43m.\u001b[49m\u001b[43mdtype\u001b[49m\u001b[43m)\u001b[49m\n",
      "\u001b[36mFile \u001b[39m\u001b[32m~/.local/lib/python3.11/site-packages/tensorflow/python/data/ops/iterator_ops.py:810\u001b[39m, in \u001b[36mOwnedIterator.__next__\u001b[39m\u001b[34m(self)\u001b[39m\n\u001b[32m    808\u001b[39m \u001b[38;5;28;01mdef\u001b[39;00m\u001b[38;5;250m \u001b[39m\u001b[34m__next__\u001b[39m(\u001b[38;5;28mself\u001b[39m):\n\u001b[32m    809\u001b[39m   \u001b[38;5;28;01mtry\u001b[39;00m:\n\u001b[32m--> \u001b[39m\u001b[32m810\u001b[39m     \u001b[38;5;28;01mreturn\u001b[39;00m \u001b[38;5;28;43mself\u001b[39;49m\u001b[43m.\u001b[49m\u001b[43m_next_internal\u001b[49m\u001b[43m(\u001b[49m\u001b[43m)\u001b[49m\n\u001b[32m    811\u001b[39m   \u001b[38;5;28;01mexcept\u001b[39;00m errors.OutOfRangeError:\n\u001b[32m    812\u001b[39m     \u001b[38;5;28;01mraise\u001b[39;00m \u001b[38;5;167;01mStopIteration\u001b[39;00m\n",
      "\u001b[36mFile \u001b[39m\u001b[32m~/.local/lib/python3.11/site-packages/tensorflow/python/data/ops/iterator_ops.py:773\u001b[39m, in \u001b[36mOwnedIterator._next_internal\u001b[39m\u001b[34m(self)\u001b[39m\n\u001b[32m    770\u001b[39m \u001b[38;5;66;03m# TODO(b/77291417): This runs in sync mode as iterators use an error status\u001b[39;00m\n\u001b[32m    771\u001b[39m \u001b[38;5;66;03m# to communicate that there is no more data to iterate over.\u001b[39;00m\n\u001b[32m    772\u001b[39m \u001b[38;5;28;01mwith\u001b[39;00m context.execution_mode(context.SYNC):\n\u001b[32m--> \u001b[39m\u001b[32m773\u001b[39m   ret = \u001b[43mgen_dataset_ops\u001b[49m\u001b[43m.\u001b[49m\u001b[43miterator_get_next\u001b[49m\u001b[43m(\u001b[49m\n\u001b[32m    774\u001b[39m \u001b[43m      \u001b[49m\u001b[38;5;28;43mself\u001b[39;49m\u001b[43m.\u001b[49m\u001b[43m_iterator_resource\u001b[49m\u001b[43m,\u001b[49m\n\u001b[32m    775\u001b[39m \u001b[43m      \u001b[49m\u001b[43moutput_types\u001b[49m\u001b[43m=\u001b[49m\u001b[38;5;28;43mself\u001b[39;49m\u001b[43m.\u001b[49m\u001b[43m_flat_output_types\u001b[49m\u001b[43m,\u001b[49m\n\u001b[32m    776\u001b[39m \u001b[43m      \u001b[49m\u001b[43moutput_shapes\u001b[49m\u001b[43m=\u001b[49m\u001b[38;5;28;43mself\u001b[39;49m\u001b[43m.\u001b[49m\u001b[43m_flat_output_shapes\u001b[49m\u001b[43m)\u001b[49m\n\u001b[32m    778\u001b[39m   \u001b[38;5;28;01mtry\u001b[39;00m:\n\u001b[32m    779\u001b[39m     \u001b[38;5;66;03m# Fast path for the case `self._structure` is not a nested structure.\u001b[39;00m\n\u001b[32m    780\u001b[39m     \u001b[38;5;28;01mreturn\u001b[39;00m \u001b[38;5;28mself\u001b[39m._element_spec._from_compatible_tensor_list(ret)  \u001b[38;5;66;03m# pylint: disable=protected-access\u001b[39;00m\n",
      "\u001b[36mFile \u001b[39m\u001b[32m~/.local/lib/python3.11/site-packages/tensorflow/python/ops/gen_dataset_ops.py:3029\u001b[39m, in \u001b[36miterator_get_next\u001b[39m\u001b[34m(iterator, output_types, output_shapes, name)\u001b[39m\n\u001b[32m   3027\u001b[39m   \u001b[38;5;28;01mreturn\u001b[39;00m _result\n\u001b[32m   3028\u001b[39m \u001b[38;5;28;01mexcept\u001b[39;00m _core._NotOkStatusException \u001b[38;5;28;01mas\u001b[39;00m e:\n\u001b[32m-> \u001b[39m\u001b[32m3029\u001b[39m   \u001b[43m_ops\u001b[49m\u001b[43m.\u001b[49m\u001b[43mraise_from_not_ok_status\u001b[49m\u001b[43m(\u001b[49m\u001b[43me\u001b[49m\u001b[43m,\u001b[49m\u001b[43m \u001b[49m\u001b[43mname\u001b[49m\u001b[43m)\u001b[49m\n\u001b[32m   3030\u001b[39m \u001b[38;5;28;01mexcept\u001b[39;00m _core._FallbackException:\n\u001b[32m   3031\u001b[39m   \u001b[38;5;28;01mpass\u001b[39;00m\n",
      "\u001b[36mFile \u001b[39m\u001b[32m~/.local/lib/python3.11/site-packages/tensorflow/python/framework/ops.py:5883\u001b[39m, in \u001b[36mraise_from_not_ok_status\u001b[39m\u001b[34m(e, name)\u001b[39m\n\u001b[32m   5881\u001b[39m \u001b[38;5;28;01mdef\u001b[39;00m\u001b[38;5;250m \u001b[39m\u001b[34mraise_from_not_ok_status\u001b[39m(e, name) -> NoReturn:\n\u001b[32m   5882\u001b[39m   e.message += (\u001b[33m\"\u001b[39m\u001b[33m name: \u001b[39m\u001b[33m\"\u001b[39m + \u001b[38;5;28mstr\u001b[39m(name \u001b[38;5;28;01mif\u001b[39;00m name \u001b[38;5;129;01mis\u001b[39;00m \u001b[38;5;129;01mnot\u001b[39;00m \u001b[38;5;28;01mNone\u001b[39;00m \u001b[38;5;28;01melse\u001b[39;00m \u001b[33m\"\u001b[39m\u001b[33m\"\u001b[39m))\n\u001b[32m-> \u001b[39m\u001b[32m5883\u001b[39m   \u001b[38;5;28;01mraise\u001b[39;00m core._status_to_exception(e) \u001b[38;5;28;01mfrom\u001b[39;00m\u001b[38;5;250m \u001b[39m\u001b[38;5;28;01mNone\u001b[39;00m\n",
      "\u001b[31mUnknownError\u001b[39m: {{function_node __wrapped__IteratorGetNext_output_types_2_device_/job:localhost/replica:0/task:0/device:CPU:0}} FileNotFoundError: [Errno 2] No such file or directory: '/home/nikola/Documents/Assignment-8/data/part_A/train_data/ground_truth/IMG_1.mat'\nTraceback (most recent call last):\n\n  File \"/home/nikola/.local/lib/python3.11/site-packages/scipy/io/matlab/_mio.py\", line 39, in _open_file\n    return open(file_like, mode), True\n           ^^^^^^^^^^^^^^^^^^^^^\n\nFileNotFoundError: [Errno 2] No such file or directory: '/home/nikola/Documents/Assignment-8/data/part_A/train_data/ground_truth/IMG_1.mat'\n\n\nDuring handling of the above exception, another exception occurred:\n\n\nTraceback (most recent call last):\n\n  File \"/home/nikola/.local/lib/python3.11/site-packages/tensorflow/python/ops/script_ops.py\", line 268, in __call__\n    return func(device, token, args)\n           ^^^^^^^^^^^^^^^^^^^^^^^^^\n\n  File \"/home/nikola/.local/lib/python3.11/site-packages/tensorflow/python/ops/script_ops.py\", line 146, in __call__\n    outputs = self._call(device, args)\n              ^^^^^^^^^^^^^^^^^^^^^^^^\n\n  File \"/home/nikola/.local/lib/python3.11/site-packages/tensorflow/python/ops/script_ops.py\", line 153, in _call\n    ret = self._func(*args)\n          ^^^^^^^^^^^^^^^^^\n\n  File \"/home/nikola/.local/lib/python3.11/site-packages/tensorflow/python/autograph/impl/api.py\", line 643, in wrapper\n    return func(*args, **kwargs)\n           ^^^^^^^^^^^^^^^^^^^^^\n\n  File \"/tmp/ipykernel_7543/1763551795.py\", line 14, in load_image_and_density\n    density = load_density_map(gt_path)\n              ^^^^^^^^^^^^^^^^^^^^^^^^^\n\n  File \"/tmp/ipykernel_7543/1763551795.py\", line 2, in load_density_map\n    mat = scipy.io.loadmat(mat_path)\n          ^^^^^^^^^^^^^^^^^^^^^^^^^^\n\n  File \"/home/nikola/.local/lib/python3.11/site-packages/scipy/io/matlab/_mio.py\", line 233, in loadmat\n    with _open_file_context(file_name, appendmat) as f:\n\n  File \"/usr/local/lib/python3.11/contextlib.py\", line 137, in __enter__\n    return next(self.gen)\n           ^^^^^^^^^^^^^^\n\n  File \"/home/nikola/.local/lib/python3.11/site-packages/scipy/io/matlab/_mio.py\", line 17, in _open_file_context\n    f, opened = _open_file(file_like, appendmat, mode)\n                ^^^^^^^^^^^^^^^^^^^^^^^^^^^^^^^^^^^^^^\n\n  File \"/home/nikola/.local/lib/python3.11/site-packages/scipy/io/matlab/_mio.py\", line 45, in _open_file\n    return open(file_like, mode), True\n           ^^^^^^^^^^^^^^^^^^^^^\n\nFileNotFoundError: [Errno 2] No such file or directory: '/home/nikola/Documents/Assignment-8/data/part_A/train_data/ground_truth/IMG_1.mat'\n\n\n\t [[{{node EagerPyFunc}}]] [Op:IteratorGetNext] name: "
     ]
    }
   ],
   "source": [
    "for img_batch, gt_batch in train_ds.take(1):\n",
    "    print(\"Image batch shape:\", img_batch.shape, img_batch.dtype)\n",
    "    print(\"GT batch shape:\", gt_batch.shape, gt_batch.dtype)\n"
   ]
  },
  {
   "cell_type": "code",
   "execution_count": null,
   "id": "00dc131d",
   "metadata": {},
   "outputs": [
    {
     "name": "stdout",
     "output_type": "stream",
     "text": [
      "Epoch 1/10\n"
     ]
    },
    {
     "ename": "ValueError",
     "evalue": "in user code:\n\n    File \"/home/nikola/.local/lib/python3.11/site-packages/keras/src/engine/training.py\", line 1401, in train_function  *\n        return step_function(self, iterator)\n    File \"/home/nikola/.local/lib/python3.11/site-packages/keras/src/engine/training.py\", line 1384, in step_function  **\n        outputs = model.distribute_strategy.run(run_step, args=(data,))\n    File \"/home/nikola/.local/lib/python3.11/site-packages/keras/src/engine/training.py\", line 1373, in run_step  **\n        outputs = model.train_step(data)\n    File \"/home/nikola/.local/lib/python3.11/site-packages/keras/src/engine/training.py\", line 1151, in train_step\n        loss = self.compute_loss(x, y, y_pred, sample_weight)\n    File \"/home/nikola/.local/lib/python3.11/site-packages/keras/src/engine/training.py\", line 1209, in compute_loss\n        return self.compiled_loss(\n    File \"/home/nikola/.local/lib/python3.11/site-packages/keras/src/engine/compile_utils.py\", line 277, in __call__\n        loss_value = loss_obj(y_t, y_p, sample_weight=sw)\n    File \"/home/nikola/.local/lib/python3.11/site-packages/keras/src/losses.py\", line 143, in __call__\n        losses = call_fn(y_true, y_pred)\n    File \"/home/nikola/.local/lib/python3.11/site-packages/keras/src/losses.py\", line 270, in call  **\n        return ag_fn(y_true, y_pred, **self._fn_kwargs)\n    File \"/home/nikola/.local/lib/python3.11/site-packages/keras/src/losses.py\", line 1706, in mean_squared_error\n        return backend.mean(tf.math.squared_difference(y_pred, y_true), axis=-1)\n\n    ValueError: Dimensions must be equal, but are 256 and 64 for '{{node mean_squared_error/SquaredDifference}} = SquaredDifference[T=DT_FLOAT](model_4/conv2d_74/BiasAdd, IteratorGetNext:1)' with input shapes: [?,256,256,1], [?,64,64,1].\n",
     "output_type": "error",
     "traceback": [
      "\u001b[31m---------------------------------------------------------------------------\u001b[39m",
      "\u001b[31mValueError\u001b[39m                                Traceback (most recent call last)",
      "\u001b[36mCell\u001b[39m\u001b[36m \u001b[39m\u001b[32mIn[22]\u001b[39m\u001b[32m, line 6\u001b[39m\n\u001b[32m      1\u001b[39m model = unet_model(output_channels=\u001b[32m1\u001b[39m)\n\u001b[32m      2\u001b[39m model.compile(optimizer=Adam(learning_rate=\u001b[32m1e-4\u001b[39m),\n\u001b[32m      3\u001b[39m               loss=MeanSquaredError(),\n\u001b[32m      4\u001b[39m               metrics=[\u001b[33m'\u001b[39m\u001b[33mmae\u001b[39m\u001b[33m'\u001b[39m])\n\u001b[32m----> \u001b[39m\u001b[32m6\u001b[39m \u001b[43mmodel\u001b[49m\u001b[43m.\u001b[49m\u001b[43mfit\u001b[49m\u001b[43m(\u001b[49m\u001b[43mtrain_ds\u001b[49m\u001b[43m,\u001b[49m\n\u001b[32m      7\u001b[39m \u001b[43m          \u001b[49m\u001b[43mvalidation_data\u001b[49m\u001b[43m=\u001b[49m\u001b[43mtest_ds\u001b[49m\u001b[43m,\u001b[49m\n\u001b[32m      8\u001b[39m \u001b[43m          \u001b[49m\u001b[43mepochs\u001b[49m\u001b[43m=\u001b[49m\u001b[32;43m10\u001b[39;49m\u001b[43m)\u001b[49m\n",
      "\u001b[36mFile \u001b[39m\u001b[32m~/.local/lib/python3.11/site-packages/keras/src/utils/traceback_utils.py:70\u001b[39m, in \u001b[36mfilter_traceback.<locals>.error_handler\u001b[39m\u001b[34m(*args, **kwargs)\u001b[39m\n\u001b[32m     67\u001b[39m     filtered_tb = _process_traceback_frames(e.__traceback__)\n\u001b[32m     68\u001b[39m     \u001b[38;5;66;03m# To get the full stack trace, call:\u001b[39;00m\n\u001b[32m     69\u001b[39m     \u001b[38;5;66;03m# `tf.debugging.disable_traceback_filtering()`\u001b[39;00m\n\u001b[32m---> \u001b[39m\u001b[32m70\u001b[39m     \u001b[38;5;28;01mraise\u001b[39;00m e.with_traceback(filtered_tb) \u001b[38;5;28;01mfrom\u001b[39;00m\u001b[38;5;250m \u001b[39m\u001b[38;5;28;01mNone\u001b[39;00m\n\u001b[32m     71\u001b[39m \u001b[38;5;28;01mfinally\u001b[39;00m:\n\u001b[32m     72\u001b[39m     \u001b[38;5;28;01mdel\u001b[39;00m filtered_tb\n",
      "\u001b[36mFile \u001b[39m\u001b[32m/tmp/__autograph_generated_filegfwnltvy.py:15\u001b[39m, in \u001b[36mouter_factory.<locals>.inner_factory.<locals>.tf__train_function\u001b[39m\u001b[34m(iterator)\u001b[39m\n\u001b[32m     13\u001b[39m \u001b[38;5;28;01mtry\u001b[39;00m:\n\u001b[32m     14\u001b[39m     do_return = \u001b[38;5;28;01mTrue\u001b[39;00m\n\u001b[32m---> \u001b[39m\u001b[32m15\u001b[39m     retval_ = ag__.converted_call(ag__.ld(step_function), (ag__.ld(\u001b[38;5;28mself\u001b[39m), ag__.ld(iterator)), \u001b[38;5;28;01mNone\u001b[39;00m, fscope)\n\u001b[32m     16\u001b[39m \u001b[38;5;28;01mexcept\u001b[39;00m:\n\u001b[32m     17\u001b[39m     do_return = \u001b[38;5;28;01mFalse\u001b[39;00m\n",
      "\u001b[31mValueError\u001b[39m: in user code:\n\n    File \"/home/nikola/.local/lib/python3.11/site-packages/keras/src/engine/training.py\", line 1401, in train_function  *\n        return step_function(self, iterator)\n    File \"/home/nikola/.local/lib/python3.11/site-packages/keras/src/engine/training.py\", line 1384, in step_function  **\n        outputs = model.distribute_strategy.run(run_step, args=(data,))\n    File \"/home/nikola/.local/lib/python3.11/site-packages/keras/src/engine/training.py\", line 1373, in run_step  **\n        outputs = model.train_step(data)\n    File \"/home/nikola/.local/lib/python3.11/site-packages/keras/src/engine/training.py\", line 1151, in train_step\n        loss = self.compute_loss(x, y, y_pred, sample_weight)\n    File \"/home/nikola/.local/lib/python3.11/site-packages/keras/src/engine/training.py\", line 1209, in compute_loss\n        return self.compiled_loss(\n    File \"/home/nikola/.local/lib/python3.11/site-packages/keras/src/engine/compile_utils.py\", line 277, in __call__\n        loss_value = loss_obj(y_t, y_p, sample_weight=sw)\n    File \"/home/nikola/.local/lib/python3.11/site-packages/keras/src/losses.py\", line 143, in __call__\n        losses = call_fn(y_true, y_pred)\n    File \"/home/nikola/.local/lib/python3.11/site-packages/keras/src/losses.py\", line 270, in call  **\n        return ag_fn(y_true, y_pred, **self._fn_kwargs)\n    File \"/home/nikola/.local/lib/python3.11/site-packages/keras/src/losses.py\", line 1706, in mean_squared_error\n        return backend.mean(tf.math.squared_difference(y_pred, y_true), axis=-1)\n\n    ValueError: Dimensions must be equal, but are 256 and 64 for '{{node mean_squared_error/SquaredDifference}} = SquaredDifference[T=DT_FLOAT](model_4/conv2d_74/BiasAdd, IteratorGetNext:1)' with input shapes: [?,256,256,1], [?,64,64,1].\n"
     ]
    }
   ],
   "source": [
    "model = unet_model(output_channels=1)\n",
    "model.compile(optimizer=Adam(learning_rate=1e-4),\n",
    "              loss=MeanSquaredError(),\n",
    "              metrics=['mae'])\n",
    "\n",
    "model.fit(train_ds,\n",
    "          validation_data=test_ds,\n",
    "          epochs=10)\n"
   ]
  },
  {
   "cell_type": "code",
   "execution_count": null,
   "id": "7ebe1505",
   "metadata": {},
   "outputs": [],
   "source": [
    "def plot_density_map(image, true_density, pred_density):\n",
    "    plt.figure(figsize=(12,4))\n",
    "    plt.subplot(1,3,1)\n",
    "    plt.imshow(image)\n",
    "    plt.title(\"Input Image\")\n",
    "    plt.axis('off')\n",
    "\n",
    "    plt.subplot(1,3,2)\n",
    "    plt.imshow(true_density[:,:,0], cmap='jet')\n",
    "    plt.title(f\"Ground Truth Count: {tf.reduce_sum(true_density):.1f}\")\n",
    "    plt.axis('off')\n",
    "\n",
    "    plt.subplot(1,3,3)\n",
    "    plt.imshow(pred_density[:,:,0], cmap='jet')\n",
    "    plt.title(f\"Predicted Count: {tf.reduce_sum(pred_density):.1f}\")\n",
    "    plt.axis('off')\n",
    "    plt.show()"
   ]
  }
 ],
 "metadata": {
  "kernelspec": {
   "display_name": "Python 3",
   "language": "python",
   "name": "python3"
  },
  "language_info": {
   "codemirror_mode": {
    "name": "ipython",
    "version": 3
   },
   "file_extension": ".py",
   "mimetype": "text/x-python",
   "name": "python",
   "nbconvert_exporter": "python",
   "pygments_lexer": "ipython3",
   "version": "3.11.8"
  }
 },
 "nbformat": 4,
 "nbformat_minor": 5
}
